2025-02-13 20:51:51,900 - get_images - INFO - Connected to node_1 at http://192.168.47.56:5001
2025-02-13 20:51:54,911 - get_images - INFO - Received metadata from node_1: {'filename': 'capture_20250213_205151_1.raw', 'timestamp': '20250213_205151', 'node_id': '1', 'size': 38154240, 'chunk_size': 65536, 'width': 1280, 'height': 720, 'camera_width': 4608, 'camera_height': 2592, 'bayer_pattern': 'RGGB'}
2025-02-13 20:51:57,359 - get_images - WARNING - Failed to connect to node_4 (http://192.168.195.56:5001): Connection refused by the server. Retrying...
2025-02-13 20:51:57,359 - get_images - WARNING - Failed to connect to node_3 (http://192.168.195.70:5001): Connection refused by the server. Retrying...
2025-02-13 20:51:57,359 - get_images - WARNING - Failed to connect to node_2 (http://192.168.195.73:5001): Connection refused by the server. Retrying...
2025-02-13 20:52:04,702 - get_images - INFO - Received complete image from node_1
2025-02-13 20:52:04,702 - get_images - ERROR - Incorrect data size. Expected: 14929920, got: 38154240
2025-02-13 20:52:04,702 - get_images - ERROR - Error processing raw data from node_1: Incorrect data size received from camera node.
Traceback (most recent call last):
  File "C:\ai\TomAISense\camera_node\testing\get_images-fast.py", line 96, in on_image_complete
    process_raw_data(received_data, metadata, node_id)
  File "C:\ai\TomAISense\camera_node\testing\get_images-fast.py", line 158, in process_raw_data
    raise ValueError("Incorrect data size received from camera node.")
ValueError: Incorrect data size received from camera node.
2025-02-13 20:52:04,702 - get_images - INFO - Image transfer time from node_1: 9.7908 seconds
2025-02-13 20:52:04,702 - get_images - INFO - Image processing time from node_1: 0.0000 seconds
2025-02-13 20:52:04,702 - get_images - INFO - Total time elapsed: 13.2759 seconds
2025-02-13 20:52:07,367 - get_images - WARNING - Failed to connect to node_2 (http://192.168.195.73:5001): Connection refused by the server. Retrying...
2025-02-13 20:52:07,368 - get_images - WARNING - Failed to connect to node_4 (http://192.168.195.56:5001): Connection refused by the server. Retrying...
2025-02-13 20:52:07,369 - get_images - WARNING - Failed to connect to node_3 (http://192.168.195.70:5001): Connection refused by the server. Retrying...
2025-02-13 20:52:07,641 - get_images - INFO - Received metadata from node_1: {'filename': 'capture_20250213_205204_1.raw', 'timestamp': '20250213_205204', 'node_id': '1', 'size': 38154240, 'chunk_size': 65536, 'width': 1280, 'height': 720, 'camera_width': 4608, 'camera_height': 2592, 'bayer_pattern': 'RGGB'}
2025-02-13 20:52:17,301 - get_images - INFO - Received complete image from node_1
2025-02-13 20:52:17,307 - get_images - ERROR - Incorrect data size. Expected: 14929920, got: 38154240
2025-02-13 20:52:17,307 - get_images - ERROR - Error processing raw data from node_1: Incorrect data size received from camera node.
Traceback (most recent call last):
  File "C:\ai\TomAISense\camera_node\testing\get_images-fast.py", line 96, in on_image_complete
    process_raw_data(received_data, metadata, node_id)
  File "C:\ai\TomAISense\camera_node\testing\get_images-fast.py", line 158, in process_raw_data
    raise ValueError("Incorrect data size received from camera node.")
ValueError: Incorrect data size received from camera node.
2025-02-13 20:52:17,308 - get_images - INFO - Image transfer time from node_1: 9.6599 seconds
2025-02-13 20:52:17,308 - get_images - INFO - Image processing time from node_1: 0.0077 seconds
2025-02-13 20:52:17,308 - get_images - INFO - Total time elapsed: 12.5997 seconds
2025-02-13 20:52:17,367 - get_images - WARNING - Failed to connect to node_2 (http://192.168.195.73:5001): Connection refused by the server. Retrying...
2025-02-13 20:52:17,368 - get_images - WARNING - Failed to connect to node_4 (http://192.168.195.56:5001): Connection refused by the server. Retrying...
2025-02-13 20:52:17,369 - get_images - WARNING - Failed to connect to node_3 (http://192.168.195.70:5001): Connection refused by the server. Retrying...
